<robot name="mobile_robot" xmlns:xacro="http://www.ros.org/wiki/xacro">
    <xacro:property name="block_length" value="0.4"/>
    <xacro:property name="block_width" value="0.2"/>
    <xacro:property name="block_height" value="0.2"/>
    <xacro:property name="main_wheel_radius" value="0.08"/>
    <xacro:property name="main_wheel_width" value="0.04"/>
    <xacro:property name="center_wheel_radius" value="0.04"/>
    <xacro:property name="center_wheel_width" value="0.02"/>
    <xacro:property name="ground_clearance" value="${center_wheel_radius}"/>
    <xacro:property name="base_mass" value="4.0"/>
    <xacro:property name="main_wheel_mass" value="0.3"/>
    <xacro:property name="center_wheel_mass" value="0.1"/>

    <xacro:macro name="box_inertia" params="mass x y z">
      <inertial>
        <mass value="${mass}"/>
        <inertia
          ixx="${mass * (y*y + z*z) / 12.0}"
          ixy="0.0"
          ixz="0.0"
          iyy="${mass * (x*x + z*z) / 12.0}"
          iyz="0.0"
          izz="${mass * (x*x + y*y) / 12.0}"/>
      </inertial>
    </xacro:macro>

    <xacro:macro name="wheel_inertia" params="mass radius width">
      <inertial>
        <mass value="${mass}"/>
        <inertia
          ixx="${mass * (3.0*radius*radius + width*width) / 12.0}"
          ixy="0.0"
          ixz="0.0"
          iyy="${mass * radius*radius / 2.0}"
          iyz="0.0"
          izz="${mass * (3.0*radius*radius + width*width) / 12.0}"/>
      </inertial>
    </xacro:macro>

    <link name="base_footprint"/>

    <link name="base_link">
      <xacro:box_inertia mass="${base_mass}" x="${block_length}" y="${block_width}" z="${block_height}"/>
      <visual>
        <geometry>
          <box size="${block_length} ${block_width} ${block_height}"/>
        </geometry>
      </visual>
      <collision>
        <geometry>
          <box size="${block_length} ${block_width} ${block_height}"/>
        </geometry>
      </collision>
    </link>

    <xacro:macro name="wheel" params="name parent x y z wheel_radius wheel_width wheel_mass">
      <link name="${name}_wheel_link">
        <xacro:wheel_inertia mass="${wheel_mass}" radius="${wheel_radius}" width="${wheel_width}"/>
        <visual>
          <origin rpy="1.5708 0 0"/>
          <geometry>
            <cylinder radius="${wheel_radius}" length="${wheel_width}"/>
          </geometry>
        </visual>
        <collision>
          <origin rpy="1.5708 0 0"/>
          <geometry>
            <cylinder radius="${wheel_radius}" length="${wheel_width}"/>
          </geometry>
        </collision>
      </link>

      <joint name="${name}_wheel_joint" type="continuous">
        <parent link="${parent}"/>
        <child link="${name}_wheel_link"/>
        <origin xyz="${x} ${y} ${z}" rpy="0 0 0"/>
        <axis xyz="0 1 0"/>
      </joint>
    </xacro:macro>

    <joint name="base_footprint_joint" type="fixed">
      <parent link="base_footprint"/>
      <child link="base_link"/>
      <origin xyz="0 0 ${block_height/2 + ground_clearance}" rpy="0 0 0"/>
    </joint>

    <xacro:wheel name="left" parent="base_link" x="-${block_length/4}" y="${block_width/2 + main_wheel_width/2}" z="${main_wheel_radius - block_height/2 - ground_clearance}" wheel_radius="${main_wheel_radius}" wheel_width="${main_wheel_width}" wheel_mass="${main_wheel_mass}"/>
    <xacro:wheel name="right" parent="base_link" x="-${block_length/4}" y="${-block_width/2 - main_wheel_width/2}" z="${main_wheel_radius - block_height/2 - ground_clearance}" wheel_radius="${main_wheel_radius}" wheel_width="${main_wheel_width}" wheel_mass="${main_wheel_mass}"/>
    <xacro:wheel name="center" parent="base_link" x="${block_length/4}" y="0" z="${center_wheel_radius - block_height/2 - ground_clearance}" wheel_radius="${center_wheel_radius}" wheel_width="${center_wheel_width}" wheel_mass="${center_wheel_mass}"/>

    <gazebo reference="base_link">
      <material>Gazebo/Blue</material>
    </gazebo>

    <gazebo reference="left_wheel_link">
      <material>Gazebo/Black</material>
      <mu1>1.0</mu1>
      <mu2>1.0</mu2>
    </gazebo>

    <gazebo reference="right_wheel_link">
      <material>Gazebo/Black</material>
      <mu1>1.0</mu1>
      <mu2>1.0</mu2>
    </gazebo>

    <gazebo reference="center_wheel_link">
      <material>Gazebo/Grey</material>
      <mu1>0.2</mu1>
      <mu2>0.2</mu2>
    </gazebo>

    <gazebo>
      <plugin
        filename="gz-sim-diff-drive-system"
        name="gz::sim::systems::DiffDrive">
        <left_joint>left_wheel_joint</left_joint>
        <right_joint>right_wheel_joint</right_joint>
        <wheel_separation>0.24</wheel_separation>
        <wheel_radius>${main_wheel_radius}</wheel_radius>
        <odom_publish_frequency>30</odom_publish_frequency>
        <max_linear_velocity>0.5</max_linear_velocity>
        <min_linear_velocity>-0.5</min_linear_velocity>
        <max_angular_velocity>1.5</max_angular_velocity>
        <min_angular_velocity>-1.5</min_angular_velocity>
      </plugin>
    </gazebo>
</robot>
